Workbook

Sheet Guide & Settings
B1: FAMILY WORLD CHAMPIONSHIP — START HERE
B2: Everything you need to understand this tracker, in plain English. If you read only this page, you’ll understand every number in the whole document.
B3: Tabs read left → right: Guide · Leaders · Dashboard · Player Card · Head-to-Head · Sport Records · Records & Awards · Trends & Stats · Match Log · Sport Voting · Poker Stake Ledger.
B5: WHAT IS THIS?
B6: A living scoreboard for our family games. Log who played and who won in the Match Log, and every other tab updates itself — rankings, head-to-heads, records, heat maps and storylines.
B8: THE ONE NUMBER THAT MATTERS — “FWC RATING”
B9: Everyone starts on 1000. Win and it rises; lose and it falls. Beating a strong player is worth more than beating a weak one (it’s an “Elo” rating, like chess). The title goes to the highest-rated ELIGIBLE and ACTIVE player — not whoever has the most wins.
B11: HOW TO ADD A GAME
B12: 1. Go to the Match Log tab — the only place you type.
B13: 2. Add ONE ROW PER PLAYER. A 1-v-1 is 2 rows; a 4-player game is 4 rows. Everyone in the same game shares the same Game ID.
B14: 3. Fill ONLY the yellow columns: Game ID, Date, Sport, Player, Result. One “Win” per game, everyone else “Loss”. For a doubles game, mark both winners “Win” and both losers “Loss”; the Check column then reads OK (team).
B15: 4. The grey columns calculate themselves and are locked. Every other tab updates instantly.
B17: WHAT EACH TAB SHOWS
B18: Leaders | D18: the current champion, the past champions (Roll of Honour) and the top player in every sport.
B19: Dashboard | D19: the full live standings, ranked by Adjusted Rating, with win %, form, streaks, movement and activity.
B20: Player Card | D20: pick any player to see their whole story — rating, rank, tier, form, activity and a sport-by-sport breakdown.
B21: Head-to-Head | D21: how each player fares directly against every other (win % in decided games, and games played together).
B22: Sport Records | D22: games, wins, win %, champion and sport-rating for every player in every sport.
B23: Records & Awards | D23: the biggest upsets, all-time records, and the season’s honours (Giant Killer, Iron Man, On Fire…).
B24: Trends & Stats | D24: the live storylines, the title race, the sport ladder, and colour heat maps for form and sport mastery.
B25: Match Log | D25: the raw record of every game — the only tab you type into.
B26: Sport Voting | D26: propose new sports or vote to remove existing ones.
B28: HOW A RATING MOVES
B29: Each game, your rating change = Skill Pts + Form Pts + Arena Pts:
B30: • Skill Pts — the main Elo swing. Win = gain, lose = drop; more for beating a favourite, less for beating an underdog.
B31: • Form Pts — a bonus or penalty for beating (or falling short of) your expected odds in that game.
B32: • Arena Pts — a small reward for turning up to group games (3+ players). The bigger the field, the more.
B34: SPORT-SPECIFIC (“BLENDED”) RATING
B35: Your predicted chance in a game is not just your overall rating. The engine also tracks how good you are at THAT sport and blends the two. The more you play a sport (about 5 games), the more your sport-specific skill takes over. So someone great overall but weak at FIFA stops being the favourite once they have a FIFA record.
B37: BECOMING CHAMPION — THE ANTI-FLUKE RULE
B38: To be crowned (Status = “Eligible”) you must have played at least 8 GAMES across at least 3 different SPORTS. Until then your Status shows “Provisional”. You must also be ACTIVE (see the Inactivity Rule). This stops a short hot streak stealing the title.
B40: ADJUSTABLE SETTINGS · change these by family vote
B41: Base Rating | C41: 1000 | D41: Everyone starts here.
B42: K-Factor (skill) | C42: 32 | D42: Size of the skill (Elo) swing. Higher = more volatile ratings.
B43: Form Weight | C43: 12 | D43: Multiplier for beating your field-adjusted odds. 0 turns Form off.
B44: Arena Weight | C44: 1 | D44: Multiplier for showing up to 3+ player games. 0 turns Arena off.
B45: Min Games to qualify | C45: 8 | D45: Games you must play before you can be crowned champion.
B46: Min Sports to qualify | C46: 3 | D46: Different sports you must play before you can be crowned champion.
B47: Idle warning (weeks) | C47: 2 | D47: Weeks idle before you’re flagged ⚠ At Risk (a warning only — no penalty yet).
B48: Idle penalty (weeks) | C48: 4 | D48: Weeks idle before the points penalty starts AND you lose the live crown until you play.
...

Sheet FWC Weekly
A1: 🏆 T H E F W C W E E K L Y
A2: THE MONDAY WRAP · with Macca and Robbo · Week ending Monday 6 July 2026
A3: YOUR HOSTS. Trent 'Macca' Maclean, thirty years in the box and a former champion himself, the biggest voice in the game and never short of a bold call. Dr Rob 'Robbo' Sinclair, ex elite competitor turned analyst, builds his own ratings models and lives for the number nobody else spotted.
A6: COLD OPEN
A7: MACCA | B7: Righto, welcome back to the Wrap. Mate, thirty years I've been doing this and I don't think I've ever read a stat sheet like this one. Nine games for the week. And Shawn played... all nine of them?
A8: ROBBO | B8: All nine. Him, Oscar and the Ferret were the only three who turned up, and Shawn didn't sit out a single game. Went three and six.
A9: MACCA | B9: Three and six. Woof.
A10: ROBBO | B10: Yeah, but hang on, because I reckon it's quietly the best week he's had all year. I'm serious. Let me get there.
A12: THE TITLE RACE
A13: MACCA | B13: Alright, ladder. Dean B still on top, eleven eighty nine. Josh behind him, then Aaron. None of them played. Again.
A14: ROBBO | B14: Not a game between them. The whole podium had the weekend off, so the only bloke actually moving is Oscar. Goes four and two, jumps Simon into fourth. Eleven oh eight.
A15: MACCA | B15: And Simon loses his spot sitting on the couch. That'd sting.
A16: ROBBO | B16: That's the format, mate. And look, Dean B hasn't played since the sixteenth of June. Nearly three weeks. You can't defend a title from the recliner forever.
A18: THE FORM DESK
A19: MACCA | B19: Who's hot, who's not.
A20: ROBBO | B20: Oscar was red hot, right up until about two o'clock Sunday. Belts Shawn four straight on the Saturday, the Kart sweep plus a Party win, then Shawn drags him to the table tennis table and does him twice. Big ones too. Plus twenty five and plus twenty two.
A21: MACCA | B21: So Oscar wins the week and still goes home filthy.
A22: ROBBO | B22: Four and two but he finishes on two losses, yeah. And spare a thought for Aaron. Five wins on the trot and nowhere to spend them. Streaks don't keep, Macca. You've got to feed them.
A24: RIVALRY CORNER
A25: MACCA | B25: Six games in two days, Oscar and Shawn. Talk to me.
A26: ROBBO | B26: Saturday it's four nil Oscar and it's getting ugly. The all time ledger's out to eleven wins to three his way at that point. Then Sunday, table tennis, and the whole thing flips. Shawn wins both and suddenly it's a different conversation.
A27: MACCA | B27: One arena. Every rivalry's got one.
A28: ROBBO | B28: That's his. And the Ferret stuff, mate, where do I even start. Twenty two games those two have played against each other now. Twenty two! Nobody else is close. Three more at Mario Party on Sunday, Ferret takes two...
A29: MACCA | B29: But.
A30: ROBBO | B30: But the one Shawn won. Twenty three per cent chance. Hold that thought, because it's basically the whole show.
A32: THE NUMBERS NOBODY IS TALKING ABOUT
A33: MACCA | B33: Go on then. Stat of the week.
A34: ROBBO | B34: Game one twenty two. Shawn over the Ferret at Mario Party, twenty three per cent win chance. Second biggest upset we've ever recorded. The only one bigger is the Ferret's own twenty percenter at FIFA back in May. So the giant killer just copped one himself.
A35: MACCA | B35: Ha! There's something beautiful about that.
A36: ROBBO | B36: There's more. Shawn's rating tonight, after forty six games, carrying the hardest draw anyone's had... one thousand. Point one. Back to the exact number we all started on.
A37: MACCA | B37: Sea level.
A38: ROBBO | B38: Sea level. Two months of getting flogged by the toughest schedule in the comp and he's dead level par. I love it. Oh, and one more. Dean B's athlete index is ninety seven point three. Next best is ten points back. The bloke's a machine. When he plays.
A39: MACCA | B39: When.
A41: WHAT WE ARE WATCHING NEXT
A42: MACCA | B42: Next week?
A43: ROBBO | B43: The rust line. Simon, Beau, Chase, David, Cody, Dean M, Dylan A. All of them tick past three weeks idle this coming weekend if they don't get a game in. The comp doesn't pay you to sit still.
A44: MACCA | B44: And the champ's nearly in the same boat.
A45: ROBBO | B45: One more quiet weekend, yeah. Aaron needs one game, any game, to keep the streak breathing. And I want the Oscar table tennis rematch. He'll be spewing about Sunday.
A46: MACCA | B46: He won't let that sit. No chance.
A47: ROBBO | B47: Book it.
...

Sheet Leaders
A1: FWC LEADERS
A2: The current leader (top eligible player) and the leader of every sport — updates live as games are logged. ℹ Every column & rule is explained on the Guide & Settings tab.
A4: CURRENT LEADER
A5: ='Sport Records'!$C$4 -> Josh
A6: ="FWC rating "&TEXT(IFERROR(INDEX(Calcs!$S$7:$S$20,MATCH('Sport Records'!$C$4,Calcs!$A$7:$A$20,0)),0),"0")&" | "&COUNTIFS('Match Log'!$D$4:$D$1510,'Sport Records'!$C$4,'Match Log'!$E$4:$E$1510,"Win")&" wins, "&(COUNTIF('Match Log'!$D$4:$D$1510,'Sport Records'!$C$4)-COUNTIFS('Match Log'!$D$4:$D$1510,'Sport Records'!$C$4,'Match Log'!$E$4:$E$1510,"Win"))&" losses"&" | highest-rated eligible and active player" -> FWC rating 1274 | 40 wins, 25 losses | highest-rated eligible and active player
A8: SPORT LEADERS · top-rated player in each sport (record shown is in that sport)
A9: Sport | B9: Leader | C9: Sport rating | D9: Record (W–L) | E9: Games
A10: =IF(Lists!$C$2="","",Lists!$C$2) -> Chess | B10: =IFERROR('Sport Records'!$P$106,"—") -> Shawn | C10: =IF(OR($B10="—",$B10=""),"",ROUND(MAX('Sport Records'!$B$106:$O$106),0)) -> 1093 | D10: =IF(OR($B10="—",$B10=""),"—",COUNTIFS('Match Log'!$D$4:$D$1510,$B10,'Match Log'!$C$4:$C$1510,$A10,'Match Log'!$E$4:$E$1510,"Win")&"–"&(COUNTIFS('Match Log'!$D$4:$D$1510,$B10,'Match Log'!$C$4:$C$1510,$A10)-COUNTIFS('Match Log'!$D$4:$D$1510,$B10,'Match Log'!$C$4:$C$1510,$A10,'Match Log'!$E$4:$E$1510,"Win"))) -> 7–0 | E10: =IFERROR('Sport Records'!$P$8,0) -> 8 | G10: ROLL OF HONOUR
A11: =IF(Lists!$C$3="","",Lists!$C$3) -> Darts | B11: =IFERROR('Sport Records'!$P$107,"—") -> Aaron | C11: =IF(OR($B11="—",$B11=""),"",ROUND(MAX('Sport Records'!$B$107:$O$107),0)) -> 1046 | D11: =IF(OR($B11="—",$B11=""),"—",COUNTIFS('Match Log'!$D$4:$D$1510,$B11,'Match Log'!$C$4:$C$1510,$A11,'Match Log'!$E$4:$E$1510,"Win")&"–"&(COUNTIFS('Match Log'!$D$4:$D$1510,$B11,'Match Log'!$C$4:$C$1510,$A11)-COUNTIFS('Match Log'!$D$4:$D$1510,$B11,'Match Log'!$C$4:$C$1510,$A11,'Match Log'!$E$4:$E$1510,"Win"))) -> 5–4 | E11: =IFERROR('Sport Records'!$P$9,0) -> 20 | G11: Family World Champions since 2019
A12: =IF(Lists!$C$4="","",Lists!$C$4) -> FIFA | B12: =IFERROR('Sport Records'!$P$108,"—") -> Aaron | C12: =IF(OR($B12="—",$B12=""),"",ROUND(MAX('Sport Records'!$B$108:$O$108),0)) -> 1099 | D12: =IF(OR($B12="—",$B12=""),"—",COUNTIFS('Match Log'!$D$4:$D$1510,$B12,'Match Log'!$C$4:$C$1510,$A12,'Match Log'!$E$4:$E$1510,"Win")&"–"&(COUNTIFS('Match Log'!$D$4:$D$1510,$B12,'Match Log'!$C$4:$C$1510,$A12)-COUNTIFS('Match Log'!$D$4:$D$1510,$B12,'Match Log'!$C$4:$C$1510,$A12,'Match Log'!$E$4:$E$1510,"Win"))) -> 11–3 | E12: =IFERROR('Sport Records'!$P$10,0) -> 31
A13: =IF(Lists!$C$5="","",Lists!$C$5) -> Golf | B13: =IFERROR('Sport Records'!$P$109,"—") -> Shawn | C13: =IF(OR($B13="—",$B13=""),"",ROUND(MAX('Sport Records'!$B$109:$O$109),0)) -> 1016 | D13: =IF(OR($B13="—",$B13=""),"—",COUNTIFS('Match Log'!$D$4:$D$1510,$B13,'Match Log'!$C$4:$C$1510,$A13,'Match Log'!$E$4:$E$1510,"Win")&"–"&(COUNTIFS('Match Log'!$D$4:$D$1510,$B13,'Match Log'!$C$4:$C$1510,$A13)-COUNTIFS('Match Log'!$D$4:$D$1510,$B13,'Match Log'!$C$4:$C$1510,$A13,'Match Log'!$E$4:$E$1510,"Win"))) -> 1–0 | E13: =IFERROR('Sport Records'!$P$11,0) -> 1 | G13: Year | H13: Champion | I13: Wooden Spoon
A14: =IF(Lists!$C$6="","",Lists!$C$6) -> Pool | B14: =IFERROR('Sport Records'!$P$110,"—") -> Simon | C14: =IF(OR($B14="—",$B14=""),"",ROUND(MAX('Sport Records'!$B$110:$O$110),0)) -> 1030 | D14: =IF(OR($B14="—",$B14=""),"—",COUNTIFS('Match Log'!$D$4:$D$1510,$B14,'Match Log'!$C$4:$C$1510,$A14,'Match Log'!$E$4:$E$1510,"Win")&"–"&(COUNTIFS('Match Log'!$D$4:$D$1510,$B14,'Match Log'!$C$4:$C$1510,$A14)-COUNTIFS('Match Log'!$D$4:$D$1510,$B14,'Match Log'!$C$4:$C$1510,$A14,'Match Log'!$E$4:$E$1510,"Win"))) -> 2–0 | E14: =IFERROR('Sport Records'!$P$12,0) -> 26 | G14: 2019 | H14: Shawn | I14: Beau
A15: =IF(Lists!$C$7="","",Lists!$C$7) -> Kelly Pool | B15: =IFERROR('Sport Records'!$P$111,"—") -> Aaron | C15: =IF(OR($B15="—",$B15=""),"",ROUND(MAX('Sport Records'!$B$111:$O$111),0)) -> 1016 | D15: =IF(OR($B15="—",$B15=""),"—",COUNTIFS('Match Log'!$D$4:$D$1510,$B15,'Match Log'!$C$4:$C$1510,$A15,'Match Log'!$E$4:$E$1510,"Win")&"–"&(COUNTIFS('Match Log'!$D$4:$D$1510,$B15,'Match Log'!$C$4:$C$1510,$A15)-COUNTIFS('Match Log'!$D$4:$D$1510,$B15,'Match Log'!$C$4:$C$1510,$A15,'Match Log'!$E$4:$E$1510,"Win"))) -> 1–0 | E15: =IFERROR('Sport Records'!$P$13,0) -> 1 | G15: 2020 | H15: Josh | I15: Aaron
A16: =IF(Lists!$C$8="","",Lists!$C$8) -> Target | B16: =IFERROR('Sport Records'!$P$112,"—") -> — | C16: =IF(OR($B16="—",$B16=""),"",ROUND(MAX('Sport Records'!$B$112:$O$112),0)) | D16: =IF(OR($B16="—",$B16=""),"—",COUNTIFS('Match Log'!$D$4:$D$1510,$B16,'Match Log'!$C$4:$C$1510,$A16,'Match Log'!$E$4:$E$1510,"Win")&"–"&(COUNTIFS('Match Log'!$D$4:$D$1510,$B16,'Match Log'!$C$4:$C$1510,$A16)-COUNTIFS('Match Log'!$D$4:$D$1510,$B16,'Match Log'!$C$4:$C$1510,$A16,'Match Log'!$E$4:$E$1510,"Win"))) -> — | E16: =IFERROR('Sport Records'!$P$14,0) -> 0 | G16: 2021 | H16: Aaron | I16: David
A17: =IF(Lists!$C$9="","",Lists!$C$9) -> Snooker | B17: =IFERROR('Sport Records'!$P$113,"—") -> — | C17: =IF(OR($B17="—",$B17=""),"",ROUND(MAX('Sport Records'!$B$113:$O$113),0)) | D17: =IF(OR($B17="—",$B17=""),"—",COUNTIFS('Match Log'!$D$4:$D$1510,$B17,'Match Log'!$C$4:$C$1510,$A17,'Match Log'!$E$4:$E$1510,"Win")&"–"&(COUNTIFS('Match Log'!$D$4:$D$1510,$B17,'Match Log'!$C$4:$C$1510,$A17)-COUNTIFS('Match Log'!$D$4:$D$1510,$B17,'Match Log'!$C$4:$C$1510,$A17,'Match Log'!$E$4:$E$1510,"Win"))) -> — | E17: =IFERROR('Sport Records'!$P$15,0) -> 0 | G17: 2022 | H17: Josh 👑 | I17: Shawn
A18: =IF(Lists!$C$10="","",Lists!$C$10) -> Putt Putt | B18: =IFERROR('Sport Records'!$P$114,"—") -> Josh | C18: =IF(OR($B18="—",$B18=""),"",ROUND(MAX('Sport Records'!$B$114:$O$114),0)) -> 1031 | D18: =IF(OR($B18="—",$B18=""),"—",COUNTIFS('Match Log'!$D$4:$D$1510,$B18,'Match Log'!$C$4:$C$1510,$A18,'Match Log'!$E$4:$E$1510,"Win")&"–"&(COUNTIFS('Match Log'!$D$4:$D$1510,$B18,'Match Log'!$C$4:$C$1510,$A18)-COUNTIFS('Match Log'!$D$4:$D$1510,$B18,'Match Log'!$C$4:$C$1510,$A18,'Match Log'!$E$4:$E$1510,"Win"))) -> 2–0 | E18: =IFERROR('Sport Records'!$P$16,0) -> 4 | G18: 2023 | H18: — not contested —
A19: =IF(Lists!$C$11="","",Lists!$C$11) -> Back Yard Putt Putt | B19: =IFERROR('Sport Records'!$P$115,"—") -> Simon | C19: =IF(OR($B19="—",$B19=""),"",ROUND(MAX('Sport Records'!$B$115:$O$115),0)) -> 1064 | D19: =IF(OR($B19="—",$B19=""),"—",COUNTIFS('Match Log'!$D$4:$D$1510,$B19,'Match Log'!$C$4:$C$1510,$A19,'Match Log'!$E$4:$E$1510,"Win")&"–"&(COUNTIFS('Match Log'!$D$4:$D$1510,$B19,'Match Log'!$C$4:$C$1510,$A19)-COUNTIFS('Match Log'!$D$4:$D$1510,$B19,'Match Log'!$C$4:$C$1510,$A19,'Match Log'!$E$4:$E$1510,"Win"))) -> 5–1 | E19: =IFERROR('Sport Records'!$P$17,0) -> 6 | G19: 2024 | H19: — not contested —
A20: =IF(Lists!$C$12="","",Lists!$C$12) -> Sting Pong | B20: =IFERROR('Sport Records'!$P$116,"—") -> — | C20: =IF(OR($B20="—",$B20=""),"",ROUND(MAX('Sport Records'!$B$116:$O$116),0)) | D20: =IF(OR($B20="—",$B20=""),"—",COUNTIFS('Match Log'!$D$4:$D$1510,$B20,'Match Log'!$C$4:$C$1510,$A20,'Match Log'!$E$4:$E$1510,"Win")&"–"&(COUNTIFS('Match Log'!$D$4:$D$1510,$B20,'Match Log'!$C$4:$C$1510,$A20)-COUNTIFS('Match Log'!$D$4:$D$1510,$B20,'Match Log'!$C$4:$C$1510,$A20,'Match Log'!$E$4:$E$1510,"Win"))) -> — | E20: =IFERROR('Sport Records'!$P$18,0) -> 0 | G20: 2025 | H20: — not contested —
A21: =IF(Lists!$C$13="","",Lists!$C$13) -> Table Tennis | B21: =IFERROR('Sport Records'!$P$117,"—") -> Shawn | C21: =IF(OR($B21="—",$B21=""),"",ROUND(MAX('Sport Records'!$B$117:$O$117),0)) -> 1119 | D21: =IF(OR($B21="—",$B21=""),"—",COUNTIFS('Match Log'!$D$4:$D$1510,$B21,'Match Log'!$C$4:$C$1510,$A21,'Match Log'!$E$4:$E$1510,"Win")&"–"&(COUNTIFS('Match Log'!$D$4:$D$1510,$B21,'Match Log'!$C$4:$C$1510,$A21)-COUNTIFS('Match Log'!$D$4:$D$1510,$B21,'Match Log'!$C$4:$C$1510,$A21,'Match Log'!$E$4:$E$1510,"Win"))) -> 13–2 | E21: =IFERROR('Sport Records'!$P$19,0) -> 56 | G21: 2026 | H21: in progress | I21: see current leader
A22: =IF(Lists!$C$14="","",Lists!$C$14) -> Mario Party | B22: =IFERROR('Sport Records'!$P$118,"—") -> Daniel (Ferret) | C22: =IF(OR($B22="—",$B22=""),"",ROUND(MAX('Sport Records'!$B$118:$O$118),0)) -> 1051 | D22: =IF(OR($B22="—",$B22=""),"—",COUNTIFS('Match Log'!$D$4:$D$1510,$B22,'Match Log'!$C$4:$C$1510,$A22,'Match Log'!$E$4:$E$1510,"Win")&"–"&(COUNTIFS('Match Log'!$D$4:$D$1510,$B22,'Match Log'!$C$4:$C$1510,$A22)-COUNTIFS('Match Log'!$D$4:$D$1510,$B22,'Match Log'!$C$4:$C$1510,$A22,'Match Log'!$E$4:$E$1510,"Win"))) -> 5–1 | E22: =IFERROR('Sport Records'!$P$20,0) -> 14
A23: =IF(Lists!$C$15="","",Lists!$C$15) -> Mario Kart | B23: =IFERROR('Sport Records'!$P$119,"—") -> Josh | C23: =IF(OR($B23="—",$B23=""),"",ROUND(MAX('Sport Records'!$B$119:$O$119),0)) -> 1055 | D23: =IF(OR($B23="—",$B23=""),"—",COUNTIFS('Match Log'!$D$4:$D$1510,$B23,'Match Log'!$C$4:$C$1510,$A23,'Match Log'!$E$4:$E$1510,"Win")&"–"&(COUNTIFS('Match Log'!$D$4:$D$1510,$B23,'Match Log'!$C$4:$C$1510,$A23)-COUNTIFS('Match Log'!$D$4:$D$1510,$B23,'Match Log'!$C$4:$C$1510,$A23,'Match Log'!$E$4:$E$1510,"Win"))) -> 6–1 | E23: =IFERROR('Sport Records'!$P$21,0) -> 23 | G23: Reigning champion: | H23: Josh (2022)
A24: =IF(Lists!$C$16="","",Lists!$C$16) -> Go Karting | B24: =IFERROR('Sport Records'!$P$120,"—") -> — | C24: =IF(OR($B24="—",$B24=""),"",ROUND(MAX('Sport Records'!$B$120:$O$120),0)) | D24: =IF(OR($B24="—",$B24=""),"—",COUNTIFS('Match Log'!$D$4:$D$1510,$B24,'Match Log'!$C$4:$C$1510,$A24,'Match Log'!$E$4:$E$1510,"Win")&"–"&(COUNTIFS('Match Log'!$D$4:$D$1510,$B24,'Match Log'!$C$4:$C$1510,$A24)-COUNTIFS('Match Log'!$D$4:$D$1510,$B24,'Match Log'!$C$4:$C$1510,$A24,'Match Log'!$E$4:$E$1510,"Win"))) -> — | E24: =IFERROR('Sport Records'!$P$22,0) -> 0 | G24: Most titles: | H24: Josh — 2 crowns
A25: =IF(Lists!$C$17="","",Lists!$C$17) -> Call of Duty | B25: =IFERROR('Sport Records'!$P$121,"—") -> Daniel (Ferret) | C25: =IF(OR($B25="—",$B25=""),"",ROUND(MAX('Sport Records'!$B$121:$O$121),0)) -> 1027 | D25: =IF(OR($B25="—",$B25=""),"—",COUNTIFS('Match Log'!$D$4:$D$1510,$B25,'Match Log'!$C$4:$C$1510,$A25,'Match Log'!$E$4:$E$1510,"Win")&"–"&(COUNTIFS('Match Log'!$D$4:$D$1510,$B25,'Match Log'!$C$4:$C$1510,$A25)-COUNTIFS('Match Log'!$D$4:$D$1510,$B25,'Match Log'!$C$4:$C$1510,$A25,'Match Log'!$E$4:$E$1510,"Win"))) -> 8–4 | E25: =IFERROR('Sport Records'!$P$23,0) -> 13
A26: =IF(Lists!$C$18="","",Lists!$C$18) -> Poker | B26: =IFERROR('Sport Records'!$P$122,"—") -> Josh | C26: =IF(OR($B26="—",$B26=""),"",ROUND(MAX('Sport Records'!$B$122:$O$122),0)) -> 1031 | D26: =IF(OR($B26="—",$B26=""),"—",COUNTIFS('Match Log'!$D$4:$D$1510,$B26,'Match Log'!$C$4:$C$1510,$A26,'Match Log'!$E$4:$E$1510,"Win")&"–"&(COUNTIFS('Match Log'!$D$4:$D$1510,$B26,'Match Log'!$C$4:$C$1510,$A26)-COUNTIFS('Match Log'!$D$4:$D$1510,$B26,'Match Log'!$C$4:$C$1510,$A26,'Match Log'!$E$4:$E$1510,"Win"))) -> 2–0 | E26: =IFERROR('Sport Records'!$P$24,0) -> 2
A27: =IF(Lists!$C$19="","",Lists!$C$19) -> ShuffleBoard | B27: =IFERROR('Sport Records'!$P$123,"—") -> Simon | C27: =IF(OR($B27="—",$B27=""),"",ROUND(MAX('Sport Records'!$B$123:$O$123),0)) -> 1060 | D27: =IF(OR($B27="—",$B27=""),"—",COUNTIFS('Match Log'!$D$4:$D$1510,$B27,'Match Log'!$C$4:$C$1510,$A27,'Match Log'!$E$4:$E$1510,"Win")&"–"&(COUNTIFS('Match Log'!$D$4:$D$1510,$B27,'Match Log'!$C$4:$C$1510,$A27)-COUNTIFS('Match Log'!$D$4:$D$1510,$B27,'Match Log'!$C$4:$C$1510,$A27,'Match Log'!$E$4:$E$1510,"Win"))) -> 8–3 | E27: =IFERROR('Sport Records'!$P$25,0) -> 31
A28: =IF(Lists!$C$20="","",Lists!$C$20) -> Mario Golf | B28: =IFERROR('Sport Records'!$P$124,"—") -> Daniel (Ferret) | C28: =IF(OR($B28="—",$B28=""),"",ROUND(MAX('Sport Records'!$B$124:$O$124),0)) -> 1121 | D28: =IF(OR($B28="—",$B28=""),"—",COUNTIFS('Match Log'!$D$4:$D$1510,$B28,'Match Log'!$C$4:$C$1510,$A28,'Match Log'!$E$4:$E$1510,"Win")&"–"&(COUNTIFS('Match Log'!$D$4:$D$1510,$B28,'Match Log'!$C$4:$C$1510,$A28)-COUNTIFS('Match Log'!$D$4:$D$1510,$B28,'Match Log'!$C$4:$C$1510,$A28,'Match Log'!$E$4:$E$1510,"Win"))) -> 25–16 | E28: =IFERROR('Sport Records'!$P$26,0) -> 57
A29: =IF(Lists!$C$21="","",Lists!$C$21) -> HORSE - Basketball | B29: =IFERROR('Sport Records'!$P$125,"—") -> Shawn | C29: =IF(OR($B29="—",$B29=""),"",ROUND(MAX('Sport Records'!$B$125:$O$125),0)) -> 1056 | D29: =IF(OR($B29="—",$B29=""),"—",COUNTIFS('Match Log'!$D$4:$D$1510,$B29,'Match Log'!$C$4:$C$1510,$A29,'Match Log'!$E$4:$E$1510,"Win")&"–"&(COUNTIFS('Match Log'!$D$4:$D$1510,$B29,'Match Log'!$C$4:$C$1510,$A29)-COUNTIFS('Match Log'!$D$4:$D$1510,$B29,'Match Log'!$C$4:$C$1510,$A29,'Match Log'!$E$4:$E$1510,"Win"))) -> 5–2 | E29: =IFERROR('Sport Records'!$P$27,0) -> 7
A30: =IF(Lists!$C$22="","",Lists!$C$22) -> Car racing arcade | B30: =IFERROR('Sport Records'!$P$126,"—") -> Dean B | C30: =IF(OR($B30="—",$B30=""),"",ROUND(MAX('Sport Records'!$B$126:$O$126),0)) -> 1058 | D30: =IF(OR($B30="—",$B30=""),"—",COUNTIFS('Match Log'!$D$4:$D$1510,$B30,'Match Log'!$C$4:$C$1510,$A30,'Match Log'!$E$4:$E$1510,"Win")&"–"&(COUNTIFS('Match Log'!$D$4:$D$1510,$B30,'Match Log'!$C$4:$C$1510,$A30)-COUNTIFS('Match Log'!$D$4:$D$1510,$B30,'Match Log'!$C$4:$C$1510,$A30,'Match Log'!$E$4:$E$1510,"Win"))) -> 4–0 | E30: =IFERROR('Sport Records'!$P$28,0) -> 6
A31: =IF(Lists!$C$23="","",Lists!$C$23) -> Shooting game arcade | B31: =IFERROR('Sport Records'!$P$127,"—") -> Shawn | C31: =IF(OR($B31="—",$B31=""),"",ROUND(MAX('Sport Records'!$B$127:$O$127),0)) -> 1017 | D31: =IF(OR($B31="—",$B31=""),"—",COUNTIFS('Match Log'!$D$4:$D$1510,$B31,'Match Log'!$C$4:$C$1510,$A31,'Match Log'!$E$4:$E$1510,"Win")&"–"&(COUNTIFS('Match Log'!$D$4:$D$1510,$B31,'Match Log'!$C$4:$C$1510,$A31)-COUNTIFS('Match Log'!$D$4:$D$1510,$B31,'Match Log'!$C$4:$C$1510,$A31,'Match Log'!$E$4:$E$1510,"Win"))) -> 1–0 | E31: =IFERROR('Sport Records'!$P$29,0) -> 2
A32: =IF(Lists!$C$24="","",Lists!$C$24) -> Cards | B32: =IFERROR('Sport Records'!$P$128,"—") -> Dean M | C32: =IF(OR($B32="—",$B32=""),"",ROUND(MAX('Sport Records'!$B$128:$O$128),0)) -> 1023 | D32: =IF(OR($B32="—",$B32=""),"—",COUNTIFS('Match Log'!$D$4:$D$1510,$B32,'Match Log'!$C$4:$C$1510,$A32,'Match Log'!$E$4:$E$1510,"Win")&"–"&(COUNTIFS('Match Log'!$D$4:$D$1510,$B32,'Match Log'!$C$4:$C$1510,$A32)-COUNTIFS('Match Log'!$D$4:$D$1510,$B32,'Match Log'!$C$4:$C$1510,$A32,'Match Log'!$E$4:$E$1510,"Win"))) -> 2–1 | E32: =IFERROR('Sport Records'!$P$30,0) -> 11
A33: =IF(Lists!$C$25="","",Lists!$C$25) -> Air Hockey | B33: =IFERROR('Sport Records'!$P$129,"—") -> Josh | C33: =IF(OR($B33="—",$B33=""),"",ROUND(MAX('Sport Records'!$B$129:$O$129),0)) -> 1015 | D33: =IF(OR($B33="—",$B33=""),"—",COUNTIFS('Match Log'!$D$4:$D$1510,$B33,'Match Log'!$C$4:$C$1510,$A33,'Match Log'!$E$4:$E$1510,"Win")&"–"&(COUNTIFS('Match Log'!$D$4:$D$1510,$B33,'Match Log'!$C$4:$C$1510,$A33)-COUNTIFS('Match Log'!$D$4:$D$1510,$B33,'Match Log'!$C$4:$C$1510,$A33,'Match Log'!$E$4:$E$1510,"Win"))) -> 2–1 | E33: =IFERROR('Sport Records'!$P$31,0) -> 3
A34: =IF(Lists!$C$26="","",Lists!$C$26) -> Basketball arcade | B34: =IFERROR('Sport Records'!$P$130,"—") -> Daniel (Ferret) | C34: =IF(OR($B34="—",$B34=""),"",ROUND(MAX('Sport Records'!$B$130:$O$130),0)) -> 1032 | D34: =IF(OR($B34="—",$B34=""),"—",COUNTIFS('Match Log'!$D$4:$D$1510,$B34,'Match Log'!$C$4:$C$1510,$A34,'Match Log'!$E$4:$E$1510,"Win")&"–"&(COUNTIFS('Match Log'!$D$4:$D$1510,$B34,'Match Log'!$C$4:$C$1510,$A34)-COUNTIFS('Match Log'!$D$4:$D$1510,$B34,'Match Log'!$C$4:$C$1510,$A34,'Match Log'!$E$4:$E$1510,"Win"))) -> 2–0 | E34: =IFERROR('Sport Records'!$P$32,0) -> 5

Sheet Dashboard
A1: FAMILY WORLD CHAMPIONSHIP
A2: Live Standings · ranked by FWC Rating (skill + form + arena from games, plus poker stakes, less idle penalties). Filter arrows on row 4 re-sort by any column. ℹ Every column & rule is explained on the Guide & Settings tab. | M2: ="Standings as of Game "&MAX('Match Log'!$A$4:$A$1510)&" · "&TEXT(MAX('Match Log'!$B$4:$B$1510),"d mmm yyyy") -> Standings as of Game 327 · 24 Oct 2026 | T2: =IF(COUNTIF($T$5:$T$18,"At risk")+COUNTIF($T$5:$T$18,"Inactive")=0,"Inactivity watch: all players active ✓","⚠ Inactivity watch: "&(COUNTIF($T$5:$T$18,"At risk")+COUNTIF($T$5:$T$18,"Inactive"))&" player(s) need a game — see Activity column") -> ⚠ Inactivity watch: 8 player(s) need a game — see Activity column
A3: ="Current Champion: "&IFERROR(INDEX($B$5:$B$18,MATCH(SUMPRODUCT(MAX(($L$5:$L$18="Eligible")*($T$5:$T$18<>"Inactive")*$V$5:$V$18)),$V$5:$V$18,0)),"— none eligible yet —") -> Current Champion: Josh
A4: Rank | B4: Player | C4: FWC Rating | D4: Games | E4: Won | F4: Lost | G4: Win % | H4: Skill Pts | I4: Form Pts | J4: Arena Pts | K4: Sports | L4: Status | M4: SoS | N4: Behind | O4: Streak | P4: Form (last 5) | Q4: Move | R4: Last Played | S4: Wks Idle | T4: Activity | U4: Penalty | V4: Adj. Rating | W4: Tier | X4: Stake Pts
A5: =ROW()-4 -> 1 | B5: =IFERROR(INDEX(Calcs!$A$7:$A$20,MATCH(LARGE(Calcs!$AI$7:$AI$20,ROW()-4),Calcs!$AI$7:$AI$20,0)),"") -> Josh | C5: =IFERROR(INDEX(Calcs!$S$7:$S$20,MATCH($B5,Calcs!$A$7:$A$20,0)),"") -> 1273.6858 | D5: =COUNTIF('Match Log'!$D$4:$D$1510,$B5) -> 65 | E5: =COUNTIFS('Match Log'!$D$4:$D$1510,$B5,'Match Log'!$E$4:$E$1510,"Win") -> 40 | F5: =$D5-$E5 -> 25 | G5: =IF($D5=0,"",$E5/$D5) -> 0.61538462 | H5: =SUMIF('Match Log'!$D$4:$D$1510,$B5,'Match Log'!$J$4:$J$1510) -> 129.80968 | I5: =SUMIF('Match Log'!$D$4:$D$1510,$B5,'Match Log'!$K$4:$K$1510) -> 72.126157 | J5: =SUMIF('Match Log'!$D$4:$D$1510,$B5,'Match Log'!$L$4:$L$1510) -> 50 | K5: =SUMPRODUCT(--(COUNTIFS('Match Log'!$D$4:$D$1510,$B5,'Match Log'!$C$4:$C$1510,Lists!$C$2:$C$26)>0)) -> 15 | L5: =IF($D5=0,"No games",IF(AND($D5>='Guide & Settings'!$C$45,$K5>='Guide & Settings'!$C$46),"Eligible","Provisional")) -> Eligible | M5: =IFERROR(INDEX(Calcs!$C$7:$C$20,MATCH($B5,Calcs!$A$7:$A$20,0)),"") -> 1137.537 | N5: =MAX($C$5:$C$18)-$C5 -> 0 | O5: =IFERROR(INDEX(Calcs!$H$7:$H$20,MATCH($B5,Calcs!$A$7:$A$20,0)),"") -> W6 | P5: =IFERROR(INDEX(Calcs!$I$7:$I$20,MATCH($B5,Calcs!$A$7:$A$20,0)),"") -> WWWWW | Q5: =IFERROR(IF(INDEX(Calcs!$L$7:$L$20,MATCH($B5,Calcs!$A$7:$A$20,0))>0,"▲"&INDEX(Calcs!$L$7:$L$20,MATCH($B5,Calcs!$A$7:$A$20,0)),IF(INDEX(Calcs!$L$7:$L$20,MATCH($B5,Calcs!$A$7:$A$20,0))<0,"▼"&ABS(INDEX(Calcs!$L$7:$L$20,MATCH($B5,Calcs!$A$7:$A$20,0))),"–")),"") -> – | R5: =IFERROR(IF(INDEX(Calcs!$P$7:$P$20,MATCH($B5,Calcs!$A$7:$A$20,0))=0,"—",TEXT(INDEX(Calcs!$P$7:$P$20,MATCH($B5,Calcs!$A$7:$A$20,0)),"d mmm")),"") -> 8 Oct | S5: =IFERROR(ROUND(INDEX(Calcs!$Q$7:$Q$20,MATCH($B5,Calcs!$A$7:$A$20,0)),1),"") -> 2.3 | T5: =IFERROR(INDEX(Calcs!$T$7:$T$20,MATCH($B5,Calcs!$A$7:$A$20,0)),"") -> At risk | U5: =IFERROR(ROUND(INDEX(Calcs!$R$7:$R$20,MATCH($B5,Calcs!$A$7:$A$20,0))+INDEX(Calcs!$U$7:$U$20,MATCH($B5,Calcs!$A$7:$A$20,0)),0),0) -> 0 | V5: =IFERROR(ROUND(INDEX(Calcs!$S$7:$S$20,MATCH($B5,Calcs!$A$7:$A$20,0)),0),"") -> 1274 | W5: =IFERROR(INDEX(Calcs!$AF$7:$AF$20,MATCH($B5,Calcs!$A$7:$A$20,0)),"") -> Elite | X5: =IFERROR(ROUND(SUMIF('Poker Stake Ledger'!$C$18:$C$137,$B5,'Poker Stake Ledger'!$K$18:$K$137),1),0) -> 21.8
A6: =ROW()-4 -> 2 | B6: =IFERROR(INDEX(Calcs!$A$7:$A$20,MATCH(LARGE(Calcs!$AI$7:$AI$20,ROW()-4),Calcs!$AI$7:$AI$20,0)),"") -> Shawn | C6: =IFERROR(INDEX(Calcs!$S$7:$S$20,MATCH($B6,Calcs!$A$7:$A$20,0)),"") -> 1228.1633 | D6: =COUNTIF('Match Log'!$D$4:$D$1510,$B6) -> 171 | E6: =COUNTIFS('Match Log'!$D$4:$D$1510,$B6,'Match Log'!$E$4:$E$1510,"Win") -> 80 | F6: =$D6-$E6 -> 91 | G6: =IF($D6=0,"",$E6/$D6) -> 0.46783626 | H6: =SUMIF('Match Log'!$D$4:$D$1510,$B6,'Match Log'!$J$4:$J$1510) -> 10.756475 | I6: =SUMIF('Match Log'!$D$4:$D$1510,$B6,'Match Log'!$K$4:$K$1510) -> 25.156854 | J6: =SUMIF('Match Log'!$D$4:$D$1510,$B6,'Match Log'!$L$4:$L$1510) -> 196 | K6: =SUMPRODUCT(--(COUNTIFS('Match Log'!$D$4:$D$1510,$B6,'Match Log'!$C$4:$C$1510,Lists!$C$2:$C$26)>0)) -> 19 | L6: =IF($D6=0,"No games",IF(AND($D6>='Guide & Settings'!$C$45,$K6>='Guide & Settings'!$C$46),"Eligible","Provisional")) -> Eligible | M6: =IFERROR(INDEX(Calcs!$C$7:$C$20,MATCH($B6,Calcs!$A$7:$A$20,0)),"") -> 1142.2912 | N6: =MAX($C$5:$C$18)-$C6 -> 45.522508 | O6: =IFERROR(INDEX(Calcs!$H$7:$H$20,MATCH($B6,Calcs!$A$7:$A$20,0)),"") -> L1 | P6: =IFERROR(INDEX(Calcs!$I$7:$I$20,MATCH($B6,Calcs!$A$7:$A$20,0)),"") -> WWLWL | Q6: =IFERROR(IF(INDEX(Calcs!$L$7:$L$20,MATCH($B6,Calcs!$A$7:$A$20,0))>0,"▲"&INDEX(Calcs!$L$7:$L$20,MATCH($B6,Calcs!$A$7:$A$20,0)),IF(INDEX(Calcs!$L$7:$L$20,MATCH($B6,Calcs!$A$7:$A$20,0))<0,"▼"&ABS(INDEX(Calcs!$L$7:$L$20,MATCH($B6,Calcs!$A$7:$A$20,0))),"–")),"") -> – | R6: =IFERROR(IF(INDEX(Calcs!$P$7:$P$20,MATCH($B6,Calcs!$A$7:$A$20,0))=0,"—",TEXT(INDEX(Calcs!$P$7:$P$20,MATCH($B6,Calcs!$A$7:$A$20,0)),"d mmm")),"") -> 24 Oct | S6: =IFERROR(ROUND(INDEX(Calcs!$Q$7:$Q$20,MATCH($B6,Calcs!$A$7:$A$20,0)),1),"") -> 0 | T6: =IFERROR(INDEX(Calcs!$T$7:$T$20,MATCH($B6,Calcs!$A$7:$A$20,0)),"") -> Active | U6: =IFERROR(ROUND(INDEX(Calcs!$R$7:$R$20,MATCH($B6,Calcs!$A$7:$A$20,0))+INDEX(Calcs!$U$7:$U$20,MATCH($B6,Calcs!$A$7:$A$20,0)),0),0) -> 0 | V6: =IFERROR(ROUND(INDEX(Calcs!$S$7:$S$20,MATCH($B6,Calcs!$A$7:$A$20,0)),0),"") -> 1228 | W6: =IFERROR(INDEX(Calcs!$AF$7:$AF$20,MATCH($B6,Calcs!$A$7:$A$20,0)),"") -> Elite | X6: =IFERROR(ROUND(SUMIF('Poker Stake Ledger'!$C$18:$C$137,$B6,'Poker Stake Ledger'!$K$18:$K$137),1),0) -> -3.8
A7: =ROW()-4 -> 3 | B7: =IFERROR(INDEX(Calcs!$A$7:$A$20,MATCH(LARGE(Calcs!$AI$7:$AI$20,ROW()-4),Calcs!$AI$7:$AI$20,0)),"") -> Aaron | C7: =IFERROR(INDEX(Calcs!$S$7:$S$20,MATCH($B7,Calcs!$A$7:$A$20,0)),"") -> 1223.1912 | D7: =COUNTIF('Match Log'!$D$4:$D$1510,$B7) -> 94 | E7: =COUNTIFS('Match Log'!$D$4:$D$1510,$B7,'Match Log'!$E$4:$E$1510,"Win") -> 44 | F7: =$D7-$E7 -> 50 | G7: =IF($D7=0,"",$E7/$D7) -> 0.46808511 | H7: =SUMIF('Match Log'!$D$4:$D$1510,$B7,'Match Log'!$J$4:$J$1510) -> 59.277239 | I7: =SUMIF('Match Log'!$D$4:$D$1510,$B7,'Match Log'!$K$4:$K$1510) -> 74.013937 | J7: =SUMIF('Match Log'!$D$4:$D$1510,$B7,'Match Log'!$L$4:$L$1510) -> 111 | K7: =SUMPRODUCT(--(COUNTIFS('Match Log'!$D$4:$D$1510,$B7,'Match Log'!$C$4:$C$1510,Lists!$C$2:$C$26)>0)) -> 14 | L7: =IF($D7=0,"No games",IF(AND($D7>='Guide & Settings'!$C$45,$K7>='Guide & Settings'!$C$46),"Eligible","Provisional")) -> Eligible | M7: =IFERROR(INDEX(Calcs!$C$7:$C$20,MATCH($B7,Calcs!$A$7:$A$20,0)),"") -> 1157.4222 | N7: =MAX($C$5:$C$18)-$C7 -> 50.494661 | O7: =IFERROR(INDEX(Calcs!$H$7:$H$20,MATCH($B7,Calcs!$A$7:$A$20,0)),"") -> W2 | P7: =IFERROR(INDEX(Calcs!$I$7:$I$20,MATCH($B7,Calcs!$A$7:$A$20,0)),"") -> LLLWW | Q7: =IFERROR(IF(INDEX(Calcs!$L$7:$L$20,MATCH($B7,Calcs!$A$7:$A$20,0))>0,"▲"&INDEX(Calcs!$L$7:$L$20,MATCH($B7,Calcs!$A$7:$A$20,0)),IF(INDEX(Calcs!$L$7:$L$20,MATCH($B7,Calcs!$A$7:$A$20,0))<0,"▼"&ABS(INDEX(Calcs!$L$7:$L$20,MATCH($B7,Calcs!$A$7:$A$20,0))),"–")),"") -> ▲2 | R7: =IFERROR(IF(INDEX(Calcs!$P$7:$P$20,MATCH($B7,Calcs!$A$7:$A$20,0))=0,"—",TEXT(INDEX(Calcs!$P$7:$P$20,MATCH($B7,Calcs!$A$7:$A$20,0)),"d mmm")),"") -> 24 Oct | S7: =IFERROR(ROUND(INDEX(Calcs!$Q$7:$Q$20,MATCH($B7,Calcs!$A$7:$A$20,0)),1),"") -> 0 | T7: =IFERROR(INDEX(Calcs!$T$7:$T$20,MATCH($B7,Calcs!$A$7:$A$20,0)),"") -> Active | U7: =IFERROR(ROUND(INDEX(Calcs!$R$7:$R$20,MATCH($B7,Calcs!$A$7:$A$20,0))+INDEX(Calcs!$U$7:$U$20,MATCH($B7,Calcs!$A$7:$A$20,0)),0),0) -> 10 | V7: =IFERROR(ROUND(INDEX(Calcs!$S$7:$S$20,MATCH($B7,Calcs!$A$7:$A$20,0)),0),"") -> 1223 | W7: =IFERROR(INDEX(Calcs!$AF$7:$AF$20,MATCH($B7,Calcs!$A$7:$A$20,0)),"") -> Elite | X7: =IFERROR(ROUND(SUMIF('Poker Stake Ledger'!$C$18:$C$137,$B7,'Poker Stake Ledger'!$K$18:$K$137),1),0) -> -11.1
A8: =ROW()-4 -> 4 | B8: =IFERROR(INDEX(Calcs!$A$7:$A$20,MATCH(LARGE(Calcs!$AI$7:$AI$20,ROW()-4),Calcs!$AI$7:$AI$20,0)),"") -> Dean B | C8: =IFERROR(INDEX(Calcs!$S$7:$S$20,MATCH($B8,Calcs!$A$7:$A$20,0)),"") -> 1177.9015 | D8: =COUNTIF('Match Log'!$D$4:$D$1510,$B8) -> 42 | E8: =COUNTIFS('Match Log'!$D$4:$D$1510,$B8,'Match Log'!$E$4:$E$1510,"Win") -> 25 | F8: =$D8-$E8 -> 17 | G8: =IF($D8=0,"",$E8/$D8) -> 0.5952381 | H8: =SUMIF('Match Log'!$D$4:$D$1510,$B8,'Match Log'!$J$4:$J$1510) -> 89.675227 | I8: =SUMIF('Match Log'!$D$4:$D$1510,$B8,'Match Log'!$K$4:$K$1510) -> 72.226314 | J8: =SUMIF('Match Log'!$D$4:$D$1510,$B8,'Match Log'!$L$4:$L$1510) -> 56 | K8: =SUMPRODUCT(--(COUNTIFS('Match Log'!$D$4:$D$1510,$B8,'Match Log'!$C$4:$C$1510,Lists!$C$2:$C$26)>0)) -> 7 | L8: =IF($D8=0,"No games",IF(AND($D8>='Guide & Settings'!$C$45,$K8>='Guide & Settings'!$C$46),"Eligible","Provisional")) -> Eligible | M8: =IFERROR(INDEX(Calcs!$C$7:$C$20,MATCH($B8,Calcs!$A$7:$A$20,0)),"") -> 1134.8881 | N8: =MAX($C$5:$C$18)-$C8 -> 95.784295 | O8: =IFERROR(INDEX(Calcs!$H$7:$H$20,MATCH($B8,Calcs!$A$7:$A$20,0)),"") -> L1 | P8: =IFERROR(INDEX(Calcs!$I$7:$I$20,MATCH($B8,Calcs!$A$7:$A$20,0)),"") -> WWLWL | Q8: =IFERROR(IF(INDEX(Calcs!$L$7:$L$20,MATCH($B8,Calcs!$A$7:$A$20,0))>0,"▲"&INDEX(Calcs!$L$7:$L$20,MATCH($B8,Calcs!$A$7:$A$20,0)),IF(INDEX(Calcs!$L$7:$L$20,MATCH($B8,Calcs!$A$7:$A$20,0))<0,"▼"&ABS(INDEX(Calcs!$L$7:$L$20,MATCH($B8,Calcs!$A$7:$A$20,0))),"–")),"") -> ▲2 | R8: =IFERROR(IF(INDEX(Calcs!$P$7:$P$20,MATCH($B8,Calcs!$A$7:$A$20,0))=0,"—",TEXT(INDEX(Calcs!$P$7:$P$20,MATCH($B8,Calcs!$A$7:$A$20,0)),"d mmm")),"") -> 25 Sep | S8: =IFERROR(ROUND(INDEX(Calcs!$Q$7:$Q$20,MATCH($B8,Calcs!$A$7:$A$20,0)),1),"") -> 4.1 | T8: =IFERROR(INDEX(Calcs!$T$7:$T$20,MATCH($B8,Calcs!$A$7:$A$20,0)),"") -> Inactive | U8: =IFERROR(ROUND(INDEX(Calcs!$R$7:$R$20,MATCH($B8,Calcs!$A$7:$A$20,0))+INDEX(Calcs!$U$7:$U$20,MATCH($B8,Calcs!$A$7:$A$20,0)),0),0) -> 40 | V8: =IFERROR(ROUND(INDEX(Calcs!$S$7:$S$20,MATCH($B8,Calcs!$A$7:$A$20,0)),0),"") -> 1178 | W8: =IFERROR(INDEX(Calcs!$AF$7:$AF$20,MATCH($B8,Calcs!$A$7:$A$20,0)),"") -> Elite | X8: =IFERROR(ROUND(SUMIF('Poker Stake Ledger'!$C$18:$C$137,$B8,'Poker Stake Ledger'!$K$18:$K$137),1),0) -> 0
A9: =ROW()-4 -> 5 | B9: =IFERROR(INDEX(Calcs!$A$7:$A$20,MATCH(LARGE(Calcs!$AI$7:$AI$20,ROW()-4),Calcs!$AI$7:$AI$20,0)),"") -> Simon | C9: =IFERROR(INDEX(Calcs!$S$7:$S$20,MATCH($B9,Calcs!$A$7:$A$20,0)),"") -> 1174.9945 | D9: =COUNTIF('Match Log'!$D$4:$D$1510,$B9) -> 44 | E9: =COUNTIFS('Match Log'!$D$4:$D$1510,$B9,'Match Log'!$E$4:$E$1510,"Win") -> 23 | F9: =$D9-$E9 -> 21 | G9: =IF($D9=0,"",$E9/$D9) -> 0.52272727 | H9: =SUMIF('Match Log'!$D$4:$D$1510,$B9,'Match Log'!$J$4:$J$1510) -> 56.427838 | I9: =SUMIF('Match Log'!$D$4:$D$1510,$B9,'Match Log'!$K$4:$K$1510) -> 65.116711 | J9: =SUMIF('Match Log'!$D$4:$D$1510,$B9,'Match Log'!$L$4:$L$1510) -> 89 | K9: =SUMPRODUCT(--(COUNTIFS('Match Log'!$D$4:$D$1510,$B9,'Match Log'!$C$4:$C$1510,Lists!$C$2:$C$26)>0)) -> 12 | L9: =IF($D9=0,"No games",IF(AND($D9>='Guide & Settings'!$C$45,$K9>='Guide & Settings'!$C$46),"Eligible","Provisional")) -> Eligible | M9: =IFERROR(INDEX(Calcs!$C$7:$C$20,MATCH($B9,Calcs!$A$7:$A$20,0)),"") -> 1088.431 | N9: =MAX($C$5:$C$18)-$C9 -> 98.691288 | O9: =IFERROR(INDEX(Calcs!$H$7:$H$20,MATCH($B9,Calcs!$A$7:$A$20,0)),"") -> W1 | P9: =IFERROR(INDEX(Calcs!$I$7:$I$20,MATCH($B9,Calcs!$A$7:$A$20,0)),"") -> WLWLW | Q9: =IFERROR(IF(INDEX(Calcs!$L$7:$L$20,MATCH($B9,Calcs!$A$7:$A$20,0))>0,"▲"&INDEX(Calcs!$L$7:$L$20,MATCH($B9,Calcs!$A$7:$A$20,0)),IF(INDEX(Calcs!$L$7:$L$20,MATCH($B9,Calcs!$A$7:$A$20,0))<0,"▼"&ABS(INDEX(Calcs!$L$7:$L$20,MATCH($B9,Calcs!$A$7:$A$20,0))),"–")),"") -> ▼2 | R9: =IFERROR(IF(INDEX(Calcs!$P$7:$P$20,MATCH($B9,Calcs!$A$7:$A$20,0))=0,"—",TEXT(INDEX(Calcs!$P$7:$P$20,MATCH($B9,Calcs!$A$7:$A$20,0)),"d mmm")),"") -> 24 Oct | S9: =IFERROR(ROUND(INDEX(Calcs!$Q$7:$Q$20,MATCH($B9,Calcs!$A$7:$A$20,0)),1),"") -> 0 | T9: =IFERROR(INDEX(Calcs!$T$7:$T$20,MATCH($B9,Calcs!$A$7:$A$20,0)),"") -> Active | U9: =IFERROR(ROUND(INDEX(Calcs!$R$7:$R$20,MATCH($B9,Calcs!$A$7:$A$20,0))+INDEX(Calcs!$U$7:$U$20,MATCH($B9,Calcs!$A$7:$A$20,0)),0),0) -> 30 | V9: =IFERROR(ROUND(INDEX(Calcs!$S$7:$S$20,MATCH($B9,Calcs!$A$7:$A$20,0)),0),"") -> 1175 | W9: =IFERROR(INDEX(Calcs!$AF$7:$AF$20,MATCH($B9,Calcs!$A$7:$A$20,0)),"") -> Elite | X9: =IFERROR(ROUND(SUMIF('Poker Stake Ledger'!$C$18:$C$137,$B9,'Poker Stake Ledger'!$K$18:$K$137),1),0) -> -5.6
A10: =ROW()-4 -> 6 | B10: =IFERROR(INDEX(Calcs!$A$7:$A$20,MATCH(LARGE(Calcs!$AI$7:$AI$20,ROW()-4),Calcs!$AI$7:$AI$20,0)),"") -> Daniel (Ferret) | C10: =IFERROR(INDEX(Calcs!$S$7:$S$20,MATCH($B10,Calcs!$A$7:$A$20,0)),"") -> 1154.9493 | D10: =COUNTIF('Match Log'!$D$4:$D$1510,$B10) -> 162 | E10: =COUNTIFS('Match Log'!$D$4:$D$1510,$B10,'Match Log'!$E$4:$E$1510,"Win") -> 69 | F10: =$D10-$E10 -> 93 | G10: =IF($D10=0,"",$E10/$D10) -> 0.42592593 | H10: =SUMIF('Match Log'!$D$4:$D$1510,$B10,'Match Log'!$J$4:$J$1510) -> -53.937029 | I10: =SUMIF('Match Log'!$D$4:$D$1510,$B10,'Match Log'!$K$4:$K$1510) -> 39.236371 | J10: =SUMIF('Match Log'!$D$4:$D$1510,$B10,'Match Log'!$L$4:$L$1510) -> 171 | K10: =SUMPRODUCT(--(COUNTIFS('Match Log'!$D$4:$D$1510,$B10,'Match Log'!$C$4:$C$1510,Lists!$C$2:$C$26)>0)) -> 20 | L10: =IF($D10=0,"No games",IF(AND($D10>='Guide & Settings'!$C$45,$K10>='Guide & Settings'!$C$46),"Eligible","Provisional")) -> Eligible | M10: =IFERROR(INDEX(Calcs!$C$7:$C$20,MATCH($B10,Calcs!$A$7:$A$20,0)),"") -> 1181.819 | N10: =MAX($C$5:$C$18)-$C10 -> 118.73649 | O10: =IFERROR(INDEX(Calcs!$H$7:$H$20,MATCH($B10,Calcs!$A$7:$A$20,0)),"") -> L2 | P10: =IFERROR(INDEX(Calcs!$I$7:$I$20,MATCH($B10,Calcs!$A$7:$A$20,0)),"") -> LLWLL | Q10: =IFERROR(IF(INDEX(Calcs!$L$7:$L$20,MATCH($B10,Calcs!$A$7:$A$20,0))>0,"▲"&INDEX(Calcs!$L$7:$L$20,MATCH($B10,Calcs!$A$7:$A$20,0)),IF(INDEX(Calcs!$L$7:$L$20,MATCH($B10,Calcs!$A$7:$A$20,0))<0,"▼"&ABS(INDEX(Calcs!$L$7:$L$20,MATCH($B10,Calcs!$A$7:$A$20,0))),"–")),"") -> ▼2 | R10: =IFERROR(IF(INDEX(Calcs!$P$7:$P$20,MATCH($B10,Calcs!$A$7:$A$20,0))=0,"—",TEXT(INDEX(Calcs!$P$7:$P$20,MATCH($B10,Calcs!$A$7:$A$20,0)),"d mmm")),"") -> 24 Oct | S10: =IFERROR(ROUND(INDEX(Calcs!$Q$7:$Q$20,MATCH($B10,Calcs!$A$7:$A$20,0)),1),"") -> 0 | T10: =IFERROR(INDEX(Calcs!$T$7:$T$20,MATCH($B10,Calcs!$A$7:$A$20,0)),"") -> Active | U10: =IFERROR(ROUND(INDEX(Calcs!$R$7:$R$20,MATCH($B10,Calcs!$A$7:$A$20,0))+INDEX(Calcs!$U$7:$U$20,MATCH($B10,Calcs!$A$7:$A$20,0)),0),0) -> 0 | V10: =IFERROR(ROUND(INDEX(Calcs!$S$7:$S$20,MATCH($B10,Calcs!$A$7:$A$20,0)),0),"") -> 1155 | W10: =IFERROR(INDEX(Calcs!$AF$7:$AF$20,MATCH($B10,Calcs!$A$7:$A$20,0)),"") -> Elite | X10: =IFERROR(ROUND(SUMIF('Poker Stake Ledger'!$C$18:$C$137,$B10,'Poker Stake Ledger'!$K$18:$K$137),1),0) -> -1.4
A11: =ROW()-4 -> 7 | B11: =IFERROR(INDEX(Calcs!$A$7:$A$20,MATCH(LARGE(Calcs!$AI$7:$AI$20,ROW()-4),Calcs!$AI$7:$AI$20,0)),"") -> Chase | C11: =IFERROR(INDEX(Calcs!$S$7:$S$20,MATCH($B11,Calcs!$A$7:$A$20,0)),"") -> 1028.0761 | D11: =COUNTIF('Match Log'!$D$4:$D$1510,$B11) -> 23 | E11: =COUNTIFS('Match Log'!$D$4:$D$1510,$B11,'Match Log'!$E$4:$E$1510,"Win") -> 9 | F11: =$D11-$E11 -> 14 | G11: =IF($D11=0,"",$E11/$D11) -> 0.39130435 | H11: =SUMIF('Match Log'!$D$4:$D$1510,$B11,'Match Log'!$J$4:$J$1510) -> 9.3432383 | I11: =SUMIF('Match Log'!$D$4:$D$1510,$B11,'Match Log'!$K$4:$K$1510) -> -8.2671353 | J11: =SUMIF('Match Log'!$D$4:$D$1510,$B11,'Match Log'!$L$4:$L$1510) -> 47 | K11: =SUMPRODUCT(--(COUNTIFS('Match Log'!$D$4:$D$1510,$B11,'Match Log'!$C$4:$C$1510,Lists!$C$2:$C$26)>0)) -> 10 | L11: =IF($D11=0,"No games",IF(AND($D11>='Guide & Settings'!$C$45,$K11>='Guide & Settings'!$C$46),"Eligible","Provisional")) -> Eligible | M11: =IFERROR(INDEX(Calcs!$C$7:$C$20,MATCH($B11,Calcs!$A$7:$A$20,0)),"") -> 1158.1954 | N11: =MAX($C$5:$C$18)-$C11 -> 245.60973 | O11: =IFERROR(INDEX(Calcs!$H$7:$H$20,MATCH($B11,Calcs!$A$7:$A$20,0)),"") -> L4 | P11: =IFERROR(INDEX(Calcs!$I$7:$I$20,MATCH($B11,Calcs!$A$7:$A$20,0)),"") -> WLLLL | Q11: =IFERROR(IF(INDEX(Calcs!$L$7:$L$20,MATCH($B11,Calcs!$A$7:$A$20,0))>0,"▲"&INDEX(Calcs!$L$7:$L$20,MATCH($B11,Calcs!$A$7:$A$20,0)),IF(INDEX(Calcs!$L$7:$L$20,MATCH($B11,Calcs!$A$7:$A$20,0))<0,"▼"&ABS(INDEX(Calcs!$L$7:$L$20,MATCH($B11,Calcs!$A$7:$A$20,0))),"–")),"") -> – | R11: =IFERROR(IF(INDEX(Calcs!$P$7:$P$20,MATCH($B11,Calcs!$A$7:$A$20,0))=0,"—",TEXT(INDEX(Calcs!$P$7:$P$20,MATCH($B11,Calcs!$A$7:$A$20,0)),"d mmm")),"") -> 2 Oct | S11: =IFERROR(ROUND(INDEX(Calcs!$Q$7:$Q$20,MATCH($B11,Calcs!$A$7:$A$20,0)),1),"") -> 3.1 | T11: =IFERROR(INDEX(Calcs!$T$7:$T$20,MATCH($B11,Calcs!$A$7:$A$20,0)),"") -> At risk | U11: =IFERROR(ROUND(INDEX(Calcs!$R$7:$R$20,MATCH($B11,Calcs!$A$7:$A$20,0))+INDEX(Calcs!$U$7:$U$20,MATCH($B11,Calcs!$A$7:$A$20,0)),0),0) -> 20 | V11: =IFERROR(ROUND(INDEX(Calcs!$S$7:$S$20,MATCH($B11,Calcs!$A$7:$A$20,0)),0),"") -> 1028 | W11: =IFERROR(INDEX(Calcs!$AF$7:$AF$20,MATCH($B11,Calcs!$A$7:$A$20,0)),"") -> Strong | X11: =IFERROR(ROUND(SUMIF('Poker Stake Ledger'!$C$18:$C$137,$B11,'Poker Stake Ledger'!$K$18:$K$137),1),0) -> 0
A12: =ROW()-4 -> 8 | B12: =IFERROR(INDEX(Calcs!$A$7:$A$20,MATCH(LARGE(Calcs!$AI$7:$AI$20,ROW()-4),Calcs!$AI$7:$AI$20,0)),"") -> Dean M | C12: =IFERROR(INDEX(Calcs!$S$7:$S$20,MATCH($B12,Calcs!$A$7:$A$20,0)),"") -> 1017.5489 | D12: =COUNTIF('Match Log'!$D$4:$D$1510,$B12) -> 15 | E12: =COUNTIFS('Match Log'!$D$4:$D$1510,$B12,'Match Log'!$E$4:$E$1510,"Win") -> 7 | F12: =$D12-$E12 -> 8 | G12: =IF($D12=0,"",$E12/$D12) -> 0.46666667 | H12: =SUMIF('Match Log'!$D$4:$D$1510,$B12,'Match Log'!$J$4:$J$1510) -> 28.076161 | I12: =SUMIF('Match Log'!$D$4:$D$1510,$B12,'Match Log'!$K$4:$K$1510) -> 24.472733 | J12: =SUMIF('Match Log'!$D$4:$D$1510,$B12,'Match Log'!$L$4:$L$1510) -> 35 | K12: =SUMPRODUCT(--(COUNTIFS('Match Log'!$D$4:$D$1510,$B12,'Match Log'!$C$4:$C$1510,Lists!$C$2:$C$26)>0)) -> 4 | L12: =IF($D12=0,"No games",IF(AND($D12>='Guide & Settings'!$C$45,$K12>='Guide & Settings'!$C$46),"Eligible","Provisional")) -> Eligible | M12: =IFERROR(INDEX(Calcs!$C$7:$C$20,MATCH($B12,Calcs!$A$7:$A$20,0)),"") -> 1065.4085 | N12: =MAX($C$5:$C$18)-$C12 -> 256.13694 | O12: =IFERROR(INDEX(Calcs!$H$7:$H$20,MATCH($B12,Calcs!$A$7:$A$20,0)),"") -> W1 | P12: =IFERROR(INDEX(Calcs!$I$7:$I$20,MATCH($B12,Calcs!$A$7:$A$20,0)),"") -> LWWLW | Q12: =IFERROR(IF(INDEX(Calcs!$L$7:$L$20,MATCH($B12,Calcs!$A$7:$A$20,0))>0,"▲"&INDEX(Calcs!$L$7:$L$20,MATCH($B12,Calcs!$A$7:$A$20,0)),IF(INDEX(Calcs!$L$7:$L$20,MATCH($B12,Calcs!$A$7:$A$20,0))<0,"▼"&ABS(INDEX(Calcs!$L$7:$L$20,MATCH($B12,Calcs!$A$7:$A$20,0))),"–")),"") -> – | R12: =IFERROR(IF(INDEX(Calcs!$P$7:$P$20,MATCH($B12,Calcs!$A$7:$A$20,0))=0,"—",TEXT(INDEX(Calcs!$P$7:$P$20,MATCH($B12,Calcs!$A$7:$A$20,0)),"d mmm")),"") -> 15 Aug | S12: =IFERROR(ROUND(INDEX(Calcs!$Q$7:$Q$20,MATCH($B12,Calcs!$A$7:$A$20,0)),1),"") -> 10 | T12: =IFERROR(INDEX(Calcs!$T$7:$T$20,MATCH($B12,Calcs!$A$7:$A$20,0)),"") -> Inactive | U12: =IFERROR(ROUND(INDEX(Calcs!$R$7:$R$20,MATCH($B12,Calcs!$A$7:$A$20,0))+INDEX(Calcs!$U$7:$U$20,MATCH($B12,Calcs!$A$7:$A$20,0)),0),0) -> 70 | V12: =IFERROR(ROUND(INDEX(Calcs!$S$7:$S$20,MATCH($B12,Calcs!$A$7:$A$20,0)),0),"") -> 1018 | W12: =IFERROR(INDEX(Calcs!$AF$7:$AF$20,MATCH($B12,Calcs!$A$7:$A$20,0)),"") -> Mid | X12: =IFERROR(ROUND(SUMIF('Poker Stake Ledger'!$C$18:$C$137,$B12,'Poker Stake Ledger'!$K$18:$K$137),1),0) -> 0
A13: =ROW()-4 -> 9 | B13: =IFERROR(INDEX(Calcs!$A$7:$A$20,MATCH(LARGE(Calcs!$AI$7:$AI$20,ROW()-4),Calcs!$AI$7:$AI$20,0)),"") -> Dylan S | C13: =IFERROR(INDEX(Calcs!$S$7:$S$20,MATCH($B13,Calcs!$A$7:$A$20,0)),"") -> 1000 | D13: =COUNTIF('Match Log'!$D$4:$D$1510,$B13) -> 0 | E13: =COUNTIFS('Match Log'!$D$4:$D$1510,$B13,'Match Log'!$E$4:$E$1510,"Win") -> 0 | F13: =$D13-$E13 -> 0 | G13: =IF($D13=0,"",$E13/$D13) | H13: =SUMIF('Match Log'!$D$4:$D$1510,$B13,'Match Log'!$J$4:$J$1510) -> 0 | I13: =SUMIF('Match Log'!$D$4:$D$1510,$B13,'Match Log'!$K$4:$K$1510) -> 0 | J13: =SUMIF('Match Log'!$D$4:$D$1510,$B13,'Match Log'!$L$4:$L$1510) -> 0 | K13: =SUMPRODUCT(--(COUNTIFS('Match Log'!$D$4:$D$1510,$B13,'Match Log'!$C$4:$C$1510,Lists!$C$2:$C$26)>0)) -> 0 | L13: =IF($D13=0,"No games",IF(AND($D13>='Guide & Settings'!$C$45,$K13>='Guide & Settings'!$C$46),"Eligible","Provisional")) -> No games | M13: =IFERROR(INDEX(Calcs!$C$7:$C$20,MATCH($B13,Calcs!$A$7:$A$20,0)),"") | N13: =MAX($C$5:$C$18)-$C13 -> 273.68584 | O13: =IFERROR(INDEX(Calcs!$H$7:$H$20,MATCH($B13,Calcs!$A$7:$A$20,0)),"") | P13: =IFERROR(INDEX(Calcs!$I$7:$I$20,MATCH($B13,Calcs!$A$7:$A$20,0)),"") | Q13: =IFERROR(IF(INDEX(Calcs!$L$7:$L$20,MATCH($B13,Calcs!$A$7:$A$20,0))>0,"▲"&INDEX(Calcs!$L$7:$L$20,MATCH($B13,Calcs!$A$7:$A$20,0)),IF(INDEX(Calcs!$L$7:$L$20,MATCH($B13,Calcs!$A$7:$A$20,0))<0,"▼"&ABS(INDEX(Calcs!$L$7:$L$20,MATCH($B13,Calcs!$A$7:$A$20,0))),"–")),"") -> – | R13: =IFERROR(IF(INDEX(Calcs!$P$7:$P$20,MATCH($B13,Calcs!$A$7:$A$20,0))=0,"—",TEXT(INDEX(Calcs!$P$7:$P$20,MATCH($B13,Calcs!$A$7:$A$20,0)),"d mmm")),"") -> — | S13: =IFERROR(ROUND(INDEX(Calcs!$Q$7:$Q$20,MATCH($B13,Calcs!$A$7:$A$20,0)),1),"") | T13: =IFERROR(INDEX(Calcs!$T$7:$T$20,MATCH($B13,Calcs!$A$7:$A$20,0)),"") -> No games | U13: =IFERROR(ROUND(INDEX(Calcs!$R$7:$R$20,MATCH($B13,Calcs!$A$7:$A$20,0))+INDEX(Calcs!$U$7:$U$20,MATCH($B13,Calcs!$A$7:$A$20,0)),0),0) -> 0 | V13: =IFERROR(ROUND(INDEX(Calcs!$S$7:$S$20,MATCH($B13,Calcs!$A$7:$A$20,0)),0),"") -> 1000 | W13: =IFERROR(INDEX(Calcs!$AF$7:$AF$20,MATCH($B13,Calcs!$A$7:$A$20,0)),"") -> No games | X13: =IFERROR(ROUND(SUMIF('Poker Stake Ledger'!$C$18:$C$137,$B13,'Poker Stake Ledger'!$K$18:$K$137),1),0) -> 0
A14: =ROW()-4 -> 10 | B14: =IFERROR(INDEX(Calcs!$A$7:$A$20,MATCH(LARGE(Calcs!$AI$7:$AI$20,ROW()-4),Calcs!$AI$7:$AI$20,0)),"") -> Oscar | C14: =IFERROR(INDEX(Calcs!$S$7:$S$20,MATCH($B14,Calcs!$A$7:$A$20,0)),"") -> 972.21011 | D14: =COUNTIF('Match Log'!$D$4:$D$1510,$B14) -> 89 | E14: =COUNTIFS('Match Log'!$D$4:$D$1510,$B14,'Match Log'!$E$4:$E$1510,"Win") -> 32 | F14: =$D14-$E14 -> 57 | G14: =IF($D14=0,"",$E14/$D14) -> 0.35955056 | H14: =SUMIF('Match Log'!$D$4:$D$1510,$B14,'Match Log'!$J$4:$J$1510) -> -95.960601 | I14: =SUMIF('Match Log'!$D$4:$D$1510,$B14,'Match Log'!$K$4:$K$1510) -> -54.829289 | J14: =SUMIF('Match Log'!$D$4:$D$1510,$B14,'Match Log'!$L$4:$L$1510) -> 123 | K14: =SUMPRODUCT(--(COUNTIFS('Match Log'!$D$4:$D$1510,$B14,'Match Log'!$C$4:$C$1510,Lists!$C$2:$C$26)>0)) -> 14 | L14: =IF($D14=0,"No games",IF(AND($D14>='Guide & Settings'!$C$45,$K14>='Guide & Settings'!$C$46),"Eligible","Provisional")) -> Eligible | M14: =IFERROR(INDEX(Calcs!$C$7:$C$20,MATCH($B14,Calcs!$A$7:$A$20,0)),"") -> 1184.8267 | N14: =MAX($C$5:$C$18)-$C14 -> 301.47573 | O14: =IFERROR(INDEX(Calcs!$H$7:$H$20,MATCH($B14,Calcs!$A$7:$A$20,0)),"") -> L1 | P14: =IFERROR(INDEX(Calcs!$I$7:$I$20,MATCH($B14,Calcs!$A$7:$A$20,0)),"") -> LWLWL | Q14: =IFERROR(IF(INDEX(Calcs!$L$7:$L$20,MATCH($B14,Calcs!$A$7:$A$20,0))>0,"▲"&INDEX(Calcs!$L$7:$L$20,MATCH($B14,Calcs!$A$7:$A$20,0)),IF(INDEX(Calcs!$L$7:$L$20,MATCH($B14,Calcs!$A$7:$A$20,0))<0,"▼"&ABS(INDEX(Calcs!$L$7:$L$20,MATCH($B14,Calcs!$A$7:$A$20,0))),"–")),"") -> ▲1 | R14: =IFERROR(IF(INDEX(Calcs!$P$7:$P$20,MATCH($B14,Calcs!$A$7:$A$20,0))=0,"—",TEXT(INDEX(Calcs!$P$7:$P$20,MATCH($B14,Calcs!$A$7:$A$20,0)),"d mmm")),"") -> 24 Oct | S14: =IFERROR(ROUND(INDEX(Calcs!$Q$7:$Q$20,MATCH($B14,Calcs!$A$7:$A$20,0)),1),"") -> 0 | T14: =IFERROR(INDEX(Calcs!$T$7:$T$20,MATCH($B14,Calcs!$A$7:$A$20,0)),"") -> Active | U14: =IFERROR(ROUND(INDEX(Calcs!$R$7:$R$20,MATCH($B14,Calcs!$A$7:$A$20,0))+INDEX(Calcs!$U$7:$U$20,MATCH($B14,Calcs!$A$7:$A$20,0)),0),0) -> 0 | V14: =IFERROR(ROUND(INDEX(Calcs!$S$7:$S$20,MATCH($B14,Calcs!$A$7:$A$20,0)),0),"") -> 972 | W14: =IFERROR(INDEX(Calcs!$AF$7:$AF$20,MATCH($B14,Calcs!$A$7:$A$20,0)),"") -> Mid | X14: =IFERROR(ROUND(SUMIF('Poker Stake Ledger'!$C$18:$C$137,$B14,'Poker Stake Ledger'!$K$18:$K$137),1),0) -> 0
A15: =ROW()-4 -> 11 | B15: =IFERROR(INDEX(Calcs!$A$7:$A$20,MATCH(LARGE(Calcs!$AI$7:$AI$20,ROW()-4),Calcs!$AI$7:$AI$20,0)),"") -> Dylan A | C15: =IFERROR(INDEX(Calcs!$S$7:$S$20,MATCH($B15,Calcs!$A$7:$A$20,0)),"") -> 970.50724 | D15: =COUNTIF('Match Log'!$D$4:$D$1510,$B15) -> 17 | E15: =COUNTIFS('Match Log'!$D$4:$D$1510,$B15,'Match Log'!$E$4:$E$1510,"Win") -> 6 | F15: =$D15-$E15 -> 11 | G15: =IF($D15=0,"",$E15/$D15) -> 0.35294118 | H15: =SUMIF('Match Log'!$D$4:$D$1510,$B15,'Match Log'!$J$4:$J$1510) -> -23.658438 | I15: =SUMIF('Match Log'!$D$4:$D$1510,$B15,'Match Log'!$K$4:$K$1510) -> -2.8343216 | J15: =SUMIF('Match Log'!$D$4:$D$1510,$B15,'Match Log'!$L$4:$L$1510) -> 37 | K15: =SUMPRODUCT(--(COUNTIFS('Match Log'!$D$4:$D$1510,$B15,'Match Log'!$C$4:$C$1510,Lists!$C$2:$C$26)>0)) -> 5 | L15: =IF($D15=0,"No games",IF(AND($D15>='Guide & Settings'!$C$45,$K15>='Guide & Settings'!$C$46),"Eligible","Provisional")) -> Eligible | M15: =IFERROR(INDEX(Calcs!$C$7:$C$20,MATCH($B15,Calcs!$A$7:$A$20,0)),"") -> 1115.8129 | N15: =MAX($C$5:$C$18)-$C15 -> 303.1786 | O15: =IFERROR(INDEX(Calcs!$H$7:$H$20,MATCH($B15,Calcs!$A$7:$A$20,0)),"") -> L8 | P15: =IFERROR(INDEX(Calcs!$I$7:$I$20,MATCH($B15,Calcs!$A$7:$A$20,0)),"") -> LLLLL | Q15: =IFERROR(IF(INDEX(Calcs!$L$7:$L$20,MATCH($B15,Calcs!$A$7:$A$20,0))>0,"▲"&INDEX(Calcs!$L$7:$L$20,MATCH($B15,Calcs!$A$7:$A$20,0)),IF(INDEX(Calcs!$L$7:$L$20,MATCH($B15,Calcs!$A$7:$A$20,0))<0,"▼"&ABS(INDEX(Calcs!$L$7:$L$20,MATCH($B15,Calcs!$A$7:$A$20,0))),"–")),"") -> ▼1 | R15: =IFERROR(IF(INDEX(Calcs!$P$7:$P$20,MATCH($B15,Calcs!$A$7:$A$20,0))=0,"—",TEXT(INDEX(Calcs!$P$7:$P$20,MATCH($B15,Calcs!$A$7:$A$20,0)),"d mmm")),"") -> 3 Oct | S15: =IFERROR(ROUND(INDEX(Calcs!$Q$7:$Q$20,MATCH($B15,Calcs!$A$7:$A$20,0)),1),"") -> 3 | T15: =IFERROR(INDEX(Calcs!$T$7:$T$20,MATCH($B15,Calcs!$A$7:$A$20,0)),"") -> At risk | U15: =IFERROR(ROUND(INDEX(Calcs!$R$7:$R$20,MATCH($B15,Calcs!$A$7:$A$20,0))+INDEX(Calcs!$U$7:$U$20,MATCH($B15,Calcs!$A$7:$A$20,0)),0),0) -> 40 | V15: =IFERROR(ROUND(INDEX(Calcs!$S$7:$S$20,MATCH($B15,Calcs!$A$7:$A$20,0)),0),"") -> 971 | W15: =IFERROR(INDEX(Calcs!$AF$7:$AF$20,MATCH($B15,Calcs!$A$7:$A$20,0)),"") -> Mid | X15: =IFERROR(ROUND(SUMIF('Poker Stake Ledger'!$C$18:$C$137,$B15,'Poker Stake Ledger'!$K$18:$K$137),1),0) -> 0
A16: =ROW()-4 -> 12 | B16: =IFERROR(INDEX(Calcs!$A$7:$A$20,MATCH(LARGE(Calcs!$AI$7:$AI$20,ROW()-4),Calcs!$AI$7:$AI$20,0)),"") -> Beau | C16: =IFERROR(INDEX(Calcs!$S$7:$S$20,MATCH($B16,Calcs!$A$7:$A$20,0)),"") -> 879.5176 | D16: =COUNTIF('Match Log'!$D$4:$D$1510,$B16) -> 10 | E16: =COUNTIFS('Match Log'!$D$4:$D$1510,$B16,'Match Log'!$E$4:$E$1510,"Win") -> 5 | F16: =$D16-$E16 -> 5 | G16: =IF($D16=0,"",$E16/$D16) -> 0.5 | H16: =SUMIF('Match Log'!$D$4:$D$1510,$B16,'Match Log'!$J$4:$J$1510) -> -14.562118 | I16: =SUMIF('Match Log'!$D$4:$D$1510,$B16,'Match Log'!$K$4:$K$1510) -> 16.079715 | J16: =SUMIF('Match Log'!$D$4:$D$1510,$B16,'Match Log'!$L$4:$L$1510) -> 28 | K16: =SUMPRODUCT(--(COUNTIFS('Match Log'!$D$4:$D$1510,$B16,'Match Log'!$C$4:$C$1510,Lists!$C$2:$C$26)>0)) -> 3 | L16: =IF($D16=0,"No games",IF(AND($D16>='Guide & Settings'!$C$45,$K16>='Guide & Settings'!$C$46),"Eligible","Provisional")) -> Eligible | M16: =IFERROR(INDEX(Calcs!$C$7:$C$20,MATCH($B16,Calcs!$A$7:$A$20,0)),"") -> 1098.1934 | N16: =MAX($C$5:$C$18)-$C16 -> 394.16824 | O16: =IFERROR(INDEX(Calcs!$H$7:$H$20,MATCH($B16,Calcs!$A$7:$A$20,0)),"") -> L2 | P16: =IFERROR(INDEX(Calcs!$I$7:$I$20,MATCH($B16,Calcs!$A$7:$A$20,0)),"") -> LWWLL | Q16: =IFERROR(IF(INDEX(Calcs!$L$7:$L$20,MATCH($B16,Calcs!$A$7:$A$20,0))>0,"▲"&INDEX(Calcs!$L$7:$L$20,MATCH($B16,Calcs!$A$7:$A$20,0)),IF(INDEX(Calcs!$L$7:$L$20,MATCH($B16,Calcs!$A$7:$A$20,0))<0,"▼"&ABS(INDEX(Calcs!$L$7:$L$20,MATCH($B16,Calcs!$A$7:$A$20,0))),"–")),"") -> – | R16: =IFERROR(IF(INDEX(Calcs!$P$7:$P$20,MATCH($B16,Calcs!$A$7:$A$20,0))=0,"—",TEXT(INDEX(Calcs!$P$7:$P$20,MATCH($B16,Calcs!$A$7:$A$20,0)),"d mmm")),"") -> 15 Jun | S16: =IFERROR(ROUND(INDEX(Calcs!$Q$7:$Q$20,MATCH($B16,Calcs!$A$7:$A$20,0)),1),"") -> 18.7 | T16: =IFERROR(INDEX(Calcs!$T$7:$T$20,MATCH($B16,Calcs!$A$7:$A$20,0)),"") -> Inactive | U16: =IFERROR(ROUND(INDEX(Calcs!$R$7:$R$20,MATCH($B16,Calcs!$A$7:$A$20,0))+INDEX(Calcs!$U$7:$U$20,MATCH($B16,Calcs!$A$7:$A$20,0)),0),0) -> 150 | V16: =IFERROR(ROUND(INDEX(Calcs!$S$7:$S$20,MATCH($B16,Calcs!$A$7:$A$20,0)),0),"") -> 880 | W16: =IFERROR(INDEX(Calcs!$AF$7:$AF$20,MATCH($B16,Calcs!$A$7:$A$20,0)),"") -> Developing | X16: =IFERROR(ROUND(SUMIF('Poker Stake Ledger'!$C$18:$C$137,$B16,'Poker Stake Ledger'!$K$18:$K$137),1),0) -> 0
... A18: =ROW()-4 -> 14 | B18: =IFERROR(INDEX(Calcs!$A$7:$A$20,MATCH(LARGE(Calcs!$AI$7:$AI$20,ROW()-4),Calcs!$AI$7:$AI$20,0)),"") -> Cody | C18: =IFERROR(INDEX(Calcs!$S$7:$S$20,MATCH($B18,Calcs!$A$7:$A$20,0)),"") -> 752.22294 | D18: =COUNTIF('Match Log'!$D$4:$D$1510,$B18) -> 15 | E18: =COUNTIFS('Match Log'!$D$4:$D$1510,$B18,'Match Log'!$E$4:$E$1510,"Win") -> 2 | F18: =$D18-$E18 -> 13 | G18: =IF($D18=0,"",$E18/$D18) -> 0.13333333 | H18: =SUMIF('Match Log'!$D$4:$D$1510,$B18,'Match Log'!$J$4:$J$1510) -> -103.26285 | I18: =SUMIF('Match Log'!$D$4:$D$1510,$B18,'Match Log'!$K$4:$K$1510) -> -42.514202 | J18: =SUMIF('Match Log'!$D$4:$D$1510,$B18,'Match Log'!$L$4:$L$1510) -> 8 | K18: =SUMPRODUCT(--(COUNTIFS('Match Log'!$D$4:$D$1510,$B18,'Match Log'!$C$4:$C$1510,Lists!$C$2:$C$26)>0)) -> 3 | L18: =IF($D18=0,"No games",IF(AND($D18>='Guide & Settings'!$C$45,$K18>='Guide & Settings'!$C$46),"Eligible","Provisional")) -> Eligible | M18: =IFERROR(INDEX(Calcs!$C$7:$C$20,MATCH($B18,Calcs!$A$7:$A$20,0)),"") -> 1128.8014 | N18: =MAX($C$5:$C$18)-$C18 -> 521.46289 | O18: =IFERROR(INDEX(Calcs!$H$7:$H$20,MATCH($B18,Calcs!$A$7:$A$20,0)),"") -> L6 | P18: =IFERROR(INDEX(Calcs!$I$7:$I$20,MATCH($B18,Calcs!$A$7:$A$20,0)),"") -> LLLLL | Q18: =IFERROR(IF(INDEX(Calcs!$L$7:$L$20,MATCH($B18,Calcs!$A$7:$A$20,0))>0,"▲"&INDEX(Calcs!$L$7:$L$20,MATCH($B18,Calcs!$A$7:$A$20,0)),IF(INDEX(Calcs!$L$7:$L$20,MATCH($B18,Calcs!$A$7:$A$20,0))<0,"▼"&ABS(INDEX(Calcs!$L$7:$L$20,MATCH($B18,Calcs!$A$7:$A$20,0))),"–")),"") -> – | R18: =IFERROR(IF(INDEX(Calcs!$P$7:$P$20,MATCH($B18,Calcs!$A$7:$A$20,0))=0,"—",TEXT(INDEX(Calcs!$P$7:$P$20,MATCH($B18,Calcs!$A$7:$A$20,0)),"d mmm")),"") -> 19 Jul | S18: =IFERROR(ROUND(INDEX(Calcs!$Q$7:$Q$20,MATCH($B18,Calcs!$A$7:$A$20,0)),1),"") -> 13.9 | T18: =IFERROR(INDEX(Calcs!$T$7:$T$20,MATCH($B18,Calcs!$A$7:$A$20,0)),"") -> Inactive | U18: =IFERROR(ROUND(INDEX(Calcs!$R$7:$R$20,MATCH($B18,Calcs!$A$7:$A$20,0))+INDEX(Calcs!$U$7:$U$20,MATCH($B18,Calcs!$A$7:$A$20,0)),0),0) -> 110 | V18: =IFERROR(ROUND(INDEX(Calcs!$S$7:$S$20,MATCH($B18,Calcs!$A$7:$A$20,0)),0),"") -> 752 | W18: =IFERROR(INDEX(Calcs!$AF$7:$AF$20,MATCH($B18,Calcs!$A$7:$A$20,0)),"") -> Developing | X18: =IFERROR(ROUND(SUMIF('Poker Stake Ledger'!$C$18:$C$137,$B18,'Poker Stake Ledger'!$K$18:$K$137),1),0) -> 0
A19: FWC Rating = 1000 + Skill Pts + Form Pts + Arena Pts + Poker Stake Pts, less any idle penalty (the Penalty column). Skill is zero-sum, and Form is zero-sum in every game with one winner. Arena rewards turning up to group games. Champion = highest-rated Eligible player who is not Inactive. Weights live on the Guide tab.

Sheet Player Card
A1: PLAYER CARD
A2: Pick any player to see their full story. Everything updates live. ℹ Every column & rule is explained on the Guide & Settings tab.
A3: Player: | B3: Josh | D3: BY SPORT
D4: Sport | E4: Games | F4: Wins | G4: Win % | H4: Sport rating
A5: Rank | B5: =IFERROR(INDEX(Dashboard!$A$5:$A$18,MATCH($B$3,Dashboard!$B$5:$B$18,0)),"") -> 1 | D5: Chess | E5: =COUNTIFS('Match Log'!$D$4:$D$1510,$B$3,'Match Log'!$C$4:$C$1510,$D5) -> 0 | F5: =COUNTIFS('Match Log'!$D$4:$D$1510,$B$3,'Match Log'!$C$4:$C$1510,$D5,'Match Log'!$E$4:$E$1510,"Win") -> 0 | G5: =IF($E5=0,"",$F5/$E5) | H5: =IFERROR(IF($E5=0,"",INDEX('Sport Records'!$B$106:$O$130,MATCH($D5,'Sport Records'!$A$106:$A$130,0),MATCH($B$3,'Sport Records'!$B$105:$O$105,0))),"")
A6: FWC Rating | B6: =IFERROR(INDEX(Dashboard!$C$5:$C$18,MATCH($B$3,Dashboard!$B$5:$B$18,0)),"") -> 1273.6858 | D6: Darts | E6: =COUNTIFS('Match Log'!$D$4:$D$1510,$B$3,'Match Log'!$C$4:$C$1510,$D6) -> 0 | F6: =COUNTIFS('Match Log'!$D$4:$D$1510,$B$3,'Match Log'!$C$4:$C$1510,$D6,'Match Log'!$E$4:$E$1510,"Win") -> 0 | G6: =IF($E6=0,"",$F6/$E6) | H6: =IFERROR(IF($E6=0,"",INDEX('Sport Records'!$B$106:$O$130,MATCH($D6,'Sport Records'!$A$106:$A$130,0),MATCH($B$3,'Sport Records'!$B$105:$O$105,0))),"")
A7: Tier | B7: =IFERROR(INDEX(Calcs!$AF$7:$AF$20,MATCH($B$3,Calcs!$A$7:$A$20,0)),"") -> Elite | D7: FIFA | E7: =COUNTIFS('Match Log'!$D$4:$D$1510,$B$3,'Match Log'!$C$4:$C$1510,$D7) -> 1 | F7: =COUNTIFS('Match Log'!$D$4:$D$1510,$B$3,'Match Log'!$C$4:$C$1510,$D7,'Match Log'!$E$4:$E$1510,"Win") -> 0 | G7: =IF($E7=0,"",$F7/$E7) -> 0 | H7: =IFERROR(IF($E7=0,"",INDEX('Sport Records'!$B$106:$O$130,MATCH($D7,'Sport Records'!$A$106:$A$130,0),MATCH($B$3,'Sport Records'!$B$105:$O$105,0))),"") -> 984
A8: Record (W–L) | B8: =IFERROR(INDEX(Dashboard!$E$5:$E$18,MATCH($B$3,Dashboard!$B$5:$B$18,0))&"–"&INDEX(Dashboard!$F$5:$F$18,MATCH($B$3,Dashboard!$B$5:$B$18,0)),"") -> 40–25 | D8: Golf | E8: =COUNTIFS('Match Log'!$D$4:$D$1510,$B$3,'Match Log'!$C$4:$C$1510,$D8) -> 0 | F8: =COUNTIFS('Match Log'!$D$4:$D$1510,$B$3,'Match Log'!$C$4:$C$1510,$D8,'Match Log'!$E$4:$E$1510,"Win") -> 0 | G8: =IF($E8=0,"",$F8/$E8) | H8: =IFERROR(IF($E8=0,"",INDEX('Sport Records'!$B$106:$O$130,MATCH($D8,'Sport Records'!$A$106:$A$130,0),MATCH($B$3,'Sport Records'!$B$105:$O$105,0))),"")
A9: Win % | B9: =IFERROR(INDEX(Dashboard!$G$5:$G$18,MATCH($B$3,Dashboard!$B$5:$B$18,0)),"") -> 0.61538462 | D9: Pool | E9: =COUNTIFS('Match Log'!$D$4:$D$1510,$B$3,'Match Log'!$C$4:$C$1510,$D9) -> 5 | F9: =COUNTIFS('Match Log'!$D$4:$D$1510,$B$3,'Match Log'!$C$4:$C$1510,$D9,'Match Log'!$E$4:$E$1510,"Win") -> 3 | G9: =IF($E9=0,"",$F9/$E9) -> 0.6 | H9: =IFERROR(IF($E9=0,"",INDEX('Sport Records'!$B$106:$O$130,MATCH($D9,'Sport Records'!$A$106:$A$130,0),MATCH($B$3,'Sport Records'!$B$105:$O$105,0))),"") -> 1016.8704
A10: Games | B10: =IFERROR(INDEX(Dashboard!$D$5:$D$18,MATCH($B$3,Dashboard!$B$5:$B$18,0)),"") -> 65 | D10: Kelly Pool | E10: =COUNTIFS('Match Log'!$D$4:$D$1510,$B$3,'Match Log'!$C$4:$C$1510,$D10) -> 1 | F10: =COUNTIFS('Match Log'!$D$4:$D$1510,$B$3,'Match Log'!$C$4:$C$1510,$D10,'Match Log'!$E$4:$E$1510,"Win") -> 0 | G10: =IF($E10=0,"",$F10/$E10) -> 0 | H10: =IFERROR(IF($E10=0,"",INDEX('Sport Records'!$B$106:$O$130,MATCH($D10,'Sport Records'!$A$106:$A$130,0),MATCH($B$3,'Sport Records'!$B$105:$O$105,0))),"") -> 997.71429
A11: Sports played | B11: =IFERROR(INDEX(Dashboard!$K$5:$K$18,MATCH($B$3,Dashboard!$B$5:$B$18,0)),"") -> 15 | D11: Target | E11: =COUNTIFS('Match Log'!$D$4:$D$1510,$B$3,'Match Log'!$C$4:$C$1510,$D11) -> 0 | F11: =COUNTIFS('Match Log'!$D$4:$D$1510,$B$3,'Match Log'!$C$4:$C$1510,$D11,'Match Log'!$E$4:$E$1510,"Win") -> 0 | G11: =IF($E11=0,"",$F11/$E11) | H11: =IFERROR(IF($E11=0,"",INDEX('Sport Records'!$B$106:$O$130,MATCH($D11,'Sport Records'!$A$106:$A$130,0),MATCH($B$3,'Sport Records'!$B$105:$O$105,0))),"")
A12: Strength of schedule | B12: =IFERROR(INDEX(Calcs!$C$7:$C$20,MATCH($B$3,Calcs!$A$7:$A$20,0)),"") -> 1137.537 | D12: Snooker | E12: =COUNTIFS('Match Log'!$D$4:$D$1510,$B$3,'Match Log'!$C$4:$C$1510,$D12) -> 0 | F12: =COUNTIFS('Match Log'!$D$4:$D$1510,$B$3,'Match Log'!$C$4:$C$1510,$D12,'Match Log'!$E$4:$E$1510,"Win") -> 0 | G12: =IF($E12=0,"",$F12/$E12) | H12: =IFERROR(IF($E12=0,"",INDEX('Sport Records'!$B$106:$O$130,MATCH($D12,'Sport Records'!$A$106:$A$130,0),MATCH($B$3,'Sport Records'!$B$105:$O$105,0))),"")
